#include <iostream>
#include <stdexcept>

int divide(int a, int b) {
    if (b == 0) {
        throw std::runtime_error("Division by zero");
    }
    return a / b;
}

int main() {
    try {
        int result = divide(10, 0);
        std::cout << result << std::endl;
    } catch (const std::exception& e) {
        std::cerr << "Error: " << e.what() << std::endl;
    }
}
